<?xml version="1.0" encoding="utf-8"?>
<!-- This URDF was automatically created by SolidWorks to URDF Exporter! Originally created by Stephen Brawner (brawner@gmail.com)
     Commit Version: 1.6.0-4-g7f85cfe  Build Version: 1.6.7995.38578
     For more information, please see http://wiki.ros.org/sw_urdf_exporter -->
<robot
  name="wl">
  <link
    name="base_link">
    <inertial>
      <origin
        xyz="-0.0205577899248541 0.00229357926072411 0.0310368876457462"
        rpy="0 0 0" />
      <mass
        value="9.92239814270616" />
      <inertia
        ixx="0.112159326570558"
        ixy="-3.56373682297612E-05"
        ixz="0.00011379640319594"
        iyy="0.0510449628843494"
        iyz="-1.05450513389096E-05"
        izz="0.088171165047631" />
    </inertial>
    <visual>
      <origin
        xyz="0 0 0"
        rpy="0 0 0" />
      <geometry>
        <mesh
          filename="../meshes/base_link.STL" />
      </geometry>
      <material
        name="">
        <color
          rgba="0.898039215686275 0.917647058823529 0.929411764705882 1" />
      </material>
    </visual>
    <collision>
      <origin
        xyz="0 0 0"
        rpy="0 0 0" />
      <geometry>
        <mesh
          filename="../meshes/base_link.STL" />
      </geometry>
    </collision>
  </link>
  <link
    name="lf0_Link">
    <inertial>
      <origin
        xyz="0.10575 0.011646 -0.011434"
        rpy="0 0 0" />
      <mass
        value="0.22671" />
      <inertia
        ixx="9.1136E-05"
        ixy="-0.0001302"
        ixz="-3.4713E-06"
        iyy="0.0011866"
        iyz="2.286E-07"
        izz="0.0012704" />
    </inertial>
    <visual>
      <origin
        xyz="0 0 0"
        rpy="0 0 0" />
      <geometry>
        <mesh
          filename="../meshes/lf0_Link.STL" />
      </geometry>
      <material
        name="">
        <color
          rgba="0.89804 0.91765 0.92941 1" />
      </material>
    </visual>
    <collision>
      <origin
        xyz="0 0 0"
        rpy="0 0 0" />
      <geometry>
        <mesh
          filename="../meshes/lf0_Link.STL" />
      </geometry>
    </collision>
  </link>
  <joint
    name="lf0_Joint"
    type="continuous">
    <origin
      xyz="-0.0077481 0.16652 0.014601"
      rpy="-1.5708 0 0" />
    <parent
      link="base_link" />
    <child
      link="lf0_Link" />
    <axis
      xyz="0 0 1" />
  </joint>
  <link
    name="lf1_Link">
    <inertial>
      <origin
        xyz="-0.11224 0.075826 0.0026978"
        rpy="0 0 0" />
      <mass
        value="0.22939" />
      <inertia
        ixx="0.00068843"
        ixy="0.00085261"
        ixz="8.3959E-08"
        iyy="0.0012947"
        iyz="-3.3773E-08"
        izz="0.0019777" />
    </inertial>
    <visual>
      <origin
        xyz="0 0 0"
        rpy="0 0 0" />
      <geometry>
        <mesh
          filename="../meshes/lf1_Link.STL" />
      </geometry>
      <material
        name="">
        <color
          rgba="1 1 1 1" />
      </material>
    </visual>
    <collision>
      <origin
        xyz="0 0 0"
        rpy="0 0 0" />
      <geometry>
        <mesh
          filename="../meshes/lf1_Link.STL" />
      </geometry>
    </collision>
  </link>
  <joint
    name="lf1_Joint"
    type="revolute">
    <origin
      xyz="0.21472 0.029422 0.0062402"
      rpy="0 0 0" />
    <parent
      link="lf0_Link" />
    <child
      link="lf1_Link" />
    <axis
      xyz="0 0 1" />
    <limit
      lower="-0.6"
      upper="0.2"
      effort="40"
      velocity="1000" />
  </joint>
  <link
    name="l_wheel_Link">
    <inertial>
      <origin
        xyz="-8.13250947467592E-05 3.03208746523093E-05 0.0334197524399316"
        rpy="0 0 0" />
      <mass
        value="0.177580655363663" />
      <inertia
        ixx="0.000177597933793852"
        ixy="8.45566081802875E-08"
        ixz="3.12245321731448E-08"
        iyy="0.000177797889428625"
        iyz="-7.71814533103985E-09"
        izz="0.000337715737740758" />
    </inertial>
    <visual>
      <origin
        xyz="0 0 0"
        rpy="0 0 0" />
      <geometry>
        <mesh
          filename="../meshes/l_wheel_Link.STL" />
      </geometry>
      <material
        name="">
        <color
          rgba="0.792156862745098 0.819607843137255 0.933333333333333 1" />
      </material>
    </visual>
    <collision>
      <origin
        xyz="0 0 0"
        rpy="0 0 0" />
      <geometry>
        <mesh
          filename="../meshes/l_wheel_Link.STL" />
      </geometry>
    </collision>
  </link>
  <joint
    name="l_wheel_Joint"
    type="continuous">
    <origin
      xyz="-0.210696556901918 0.141859628740362 -0.00599999999999937"
      rpy="0 0 0" />
    <parent
      link="lf1_Link" />
    <child
      link="l_wheel_Link" />
    <axis
      xyz="0 0 1" />
  </joint>
  <link
    name="rf0_Link">
    <inertial>
      <origin
        xyz="0.106837199546385 -0.0131767469599098 -0.0107525096247883"
        rpy="0 0 0" />
      <mass
        value="0.237147723000171" />
      <inertia
        ixx="9.68060329290281E-05"
        ixy="0.000146443536553271"
        ixz="-3.47438122043599E-06"
        iyy="0.00118529098607326"
        iyz="-1.75449453588467E-07"
        izz="0.00127422875302358" />
    </inertial>
    <visual>
      <origin
        xyz="0 0 0"
        rpy="0 0 0" />
      <geometry>
        <mesh
          filename="../meshes/rf0_Link.STL" />
      </geometry>
      <material
        name="">
        <color
          rgba="1 1 1 1" />
      </material>
    </visual>
    <collision>
      <origin
        xyz="0 0 0"
        rpy="0 0 0" />
      <geometry>
        <mesh
          filename="../meshes/rf0_Link.STL" />
      </geometry>
    </collision>
  </link>
  <joint
    name="rf0_Joint"
    type="continuous">
    <origin
      xyz="-0.00767633558745229 -0.176803872353463 0.0142033835799731"
      rpy="1.5707963267949 0 0" />
    <parent
      link="base_link" />
    <child
      link="rf0_Link" />
    <axis
      xyz="0 0 1" />
  </joint>
  <link
    name="rf1_Link">
    <inertial>
      <origin
        xyz="-0.111744733599728 -0.075974782411244 0.00281569417974681"
        rpy="0 0 0" />
      <mass
        value="0.229390429090394" />
      <inertia
        ixx="0.000685956396128991"
        ixy="-0.000856378759038052"
        ixz="-5.71763521995569E-08"
        iyy="0.00129712025985927"
        iyz="6.48611173031919E-08"
        izz="0.00197771770068823" />
    </inertial>
    <visual>
      <origin
        xyz="0 0 0"
        rpy="0 0 0" />
      <geometry>
        <mesh
          filename="../meshes/rf1_Link.STL" />
      </geometry>
      <material
        name="">
        <color
          rgba="1 1 1 1" />
      </material>
    </visual>
    <collision>
      <origin
        xyz="0 0 0"
        rpy="0 0 0" />
      <geometry>
        <mesh
          filename="../meshes/rf1_Link.STL" />
      </geometry>
    </collision>
  </link>
  <joint
    name="rf1_Joint"
    type="revolute">
    <origin
      xyz="0.21416 -0.032328 0.0062402"
      rpy="0 0 0" />
    <parent
      link="rf0_Link" />
    <child
      link="rf1_Link" />
    <axis
      xyz="0 0 1" />
    <limit
      lower="-0.2"
      upper="0.6"
      effort="40"
      velocity="1000" />
  </joint>
  <link
    name="r_wheel_Link">
    <inertial>
      <origin
        xyz="-1.61475375610731E-05 8.52785299987752E-05 0.0334197525201289"
        rpy="0 0 0" />
      <mass
        value="0.177580658617343" />
      <inertia
        ixx="0.000177819218723046"
        ixy="4.92959386063319E-08"
        ixz="9.55694732861707E-09"
        iyy="0.000177576605205523"
        iyz="-3.07118758989423E-08"
        izz="0.000337715738202895" />
    </inertial>
    <visual>
      <origin
        xyz="0 0 0"
        rpy="0 0 0" />
      <geometry>
        <mesh
          filename="../meshes/r_wheel_Link.STL" />
      </geometry>
      <material
        name="">
        <color
          rgba="0.792156862745098 0.819607843137255 0.933333333333333 1" />
      </material>
    </visual>
    <collision>
      <origin
        xyz="0 0 0"
        rpy="0 0 0" />
      <geometry>
        <mesh
          filename="../meshes/r_wheel_Link.STL" />
      </geometry>
    </collision>
  </link>
  <joint
    name="r_wheel_Joint"
    type="continuous">
    <origin
      xyz="-0.210696556901869 -0.141859628740493 -0.00599999999999556"
      rpy="0 0 0" />
    <parent
      link="rf1_Link" />
    <child
      link="r_wheel_Link" />
    <axis
      xyz="0 0 1" />
  </joint>
</robot>
